Workbook
Name Embark: dEmbarks[Embark]
Name ListaClientes: dClientes[Client]
Name ListaRigs: dRig[Rig]
Name SegmentaçãodeDados_Client: #N/A
Name SegmentaçãodeDados_Rig: #N/A
Name SoW: dSoWDetail[SoW]
Name WO: dWOs[WO]

Sheet Planilha3
A5: Soma de Total | B5: Rótulos de Coluna
A6: Rótulos de Linha | B6: (vazio) | C6: 45658 | D6: 45689 | E6: 45717 | F6: Total Geral
A7: (vazio) | B7: 172843.88 | C7: 8162857.9 | D7: 11040023 | E7: 4327137.4 | F7: 23702862
A8: 1328 | B8: 172843.88 | C8: 8162857.9 | D8: 11040023 | E8: 4327137.4 | F8: 23702862
A9: 1641 | B9: 172843.88 | C9: 8162857.9 | D9: 11040023 | E9: 4327137.4 | F9: 23702862
A10: 1656 | B10: 172843.88 | C10: 8162857.9 | D10: 11040023 | E10: 4327137.4 | F10: 23702862
A11: 1671 | B11: 172843.88 | C11: 8162857.9 | D11: 11040023 | E11: 4327137.4 | F11: 23702862
A12: 1713 | B12: 172843.88 | C12: 8162857.9 | D12: 11040023 | E12: 4327137.4 | F12: 23702862
A13: 1729 | B13: 172843.88 | C13: 8162857.9 | D13: 11040023 | E13: 4327137.4 | F13: 23702862
A14: 1730 | B14: 172843.88 | C14: 8162857.9 | D14: 11040023 | E14: 4327137.4 | F14: 23702862
A15: 1737 | B15: 172843.88 | C15: 8162857.9 | D15: 11040023 | E15: 4327137.4 | F15: 23702862
A16: 1739 | B16: 172843.88 | C16: 8162857.9 | D16: 11040023 | E16: 4327137.4 | F16: 23702862
A17: 1742 | B17: 172843.88 | C17: 8162857.9 | D17: 11040023 | E17: 4327137.4 | F17: 23702862
A18: 1746 | B18: 172843.88 | C18: 8162857.9 | D18: 11040023 | E18: 4327137.4 | F18: 23702862
A19: 1754 | B19: 172843.88 | C19: 8162857.9 | D19: 11040023 | E19: 4327137.4 | F19: 23702862
... A1035: 3360 | B1035: 172843.88 | C1035: 8162857.9 | D1035: 11040023 | E1035: 4327137.4 | F1035: 23702862
A1036: Total Geral | B1036: 172843.88 | C1036: 8162857.9 | D1036: 11040023 | E1036: 4327137.4 | F1036: 23702862

Sheet Input
A1: Month | B1: E/F | C1: Embark | D1: WO | E1: Contract Category | F1: Cliente | G1: Rig | H1: Quote | I1: Start Date | J1: End Date | K1: Amount Charged | L1: Value | M1: Pending Amount | N1: DI | O1: DI Date | P1: Number of Invoice | Q1: InvoiceTotal Value | R1: Invoice Date | S1: Days NF-Des | T1: Rental Equipment Invoice (REI) | U1: Rental Equipment Invoice Value | V1: REI Date | W1: Days FL-Des | X1: WIP | Y1: Daily | Z1: Stand-by | AA1: Total Daily | AB1: Personal | AC1: Stand-by $ | AD1: Personel Logistics | AE1: Hotel / Meal | AF1: Equipment In Transit | AG1: Material | AH1: Log de Materials | AI1: Exchange rate variation | AJ1: LOP | AK1: Tags & Slings | AL1: Extra Time | AM1: Others | AN1: ART (Technical Responsibility) | AO1: Engineering | AP1: Total | AQ1: Ticket Médio
A2: 46054 | B2: F | D2: 3344 | E2: Inspection Contract - Variable | F2: Modec | G2: MV-24 | H2: 4711 | I2: 45858 | J2: 45897 | K2: 47.14 | L2: =SUM(TabProd[[#This Row],[Personal]:[Engineering]]) -> 47.14 | M2: =IF(TabProd[[#This Row],[Amount Charged]]<>TabProd[[#This Row],[Value]],TabProd[[#This Row],[Amount Charged]]-TabProd[[#This Row],[Value]],"") | N2: 4914 | O2: 46010 | P2: 1721 | Q2: 47.14 | R2: 46066 | S2: =IF(R2="","",R2-J2) -> 169 | W2: =IF(V2="","",V2-J2) | X2: =TabProd[[#This Row],[Value]]-TabProd[[#This Row],[InvoiceTotal Value]]-TabProd[[#This Row],[Rental Equipment Invoice Value]]+AR1 -> 0 | Y2: 11 | AA2: =SUM(Y2:Z2) -> 11 | AB2: 47.14 | AP2: =SUM(AB2:AO2) -> 47.14 | AQ2: =IF(TabProd[[#This Row],[Total Daily]]=0,"",TabProd[[#This Row],[Total]]/TabProd[[#This Row],[Total Daily]]) -> 4.2854545
A3: 46023 | B3: F | D3: 3445 | E3: Engineering | F3: Helix | G3: SH2 | H3: 4912 | I3: 45901 | J3: 45930 | K3: -22800 | L3: =SUM(TabProd[[#This Row],[Personal]:[Engineering]]) -> -22800 | M3: =IF(TabProd[[#This Row],[Amount Charged]]<>TabProd[[#This Row],[Value]],TabProd[[#This Row],[Amount Charged]]-TabProd[[#This Row],[Value]],"") | N3: 5089 | O3: 45932 | P3: 0 | Q3: -22800 | S3: =IF(R3="","",R3-J3) | W3: =IF(V3="","",V3-J3) | X3: =TabProd[[#This Row],[Value]]-TabProd[[#This Row],[InvoiceTotal Value]]-TabProd[[#This Row],[Rental Equipment Invoice Value]]+AR3 -> 0 | AA3: =SUM(Y3:Z3) -> 0 | AO3: -22800 | AP3: =SUM(AB3:AO3) -> -22800 | AQ3: =IF(TabProd[[#This Row],[Total Daily]]=0,"",TabProd[[#This Row],[Total]]/TabProd[[#This Row],[Total Daily]])
A4: 46023 | B4: F | D4: 3573 | E4: Inspection Spot | F4: Oceaneering | G4: PBS | H4: 5136 | I4: 45918 | J4: 45921 | K4: -13814.4 | L4: =SUM(TabProd[[#This Row],[Personal]:[Engineering]]) -> -13814.4 | M4: =IF(TabProd[[#This Row],[Amount Charged]]<>TabProd[[#This Row],[Value]],TabProd[[#This Row],[Amount Charged]]-TabProd[[#This Row],[Value]],"") | N4: 5085 | O4: 45930 | P4: 3912 | Q4: -13814.4 | R4: 45968 | S4: =IF(R4="","",R4-J4) -> 47 | W4: =IF(V4="","",V4-J4) | X4: =TabProd[[#This Row],[Value]]-TabProd[[#This Row],[InvoiceTotal Value]]-TabProd[[#This Row],[Rental Equipment Invoice Value]]+AR3 -> 1.8189894e-12 | Y4: -6 | AA4: =SUM(Y4:Z4) -> -6 | AB4: -12614.4 | AG4: -1200 | AP4: =SUM(AB4:AO4) -> -13814.4 | AQ4: =IF(TabProd[[#This Row],[Total Daily]]=0,"",TabProd[[#This Row],[Total]]/TabProd[[#This Row],[Total Daily]]) -> 2302.4
A5: 46023 | B5: F | D5: 3475 | E5: Inspection Contract - Variable | F5: Transocean | G5: Corcovado | H5: 4881 | I5: 45929 | J5: 45933 | K5: -148800.8 | L5: =SUM(TabProd[[#This Row],[Personal]:[Engineering]]) -> -148800.8 | M5: =IF(TabProd[[#This Row],[Amount Charged]]<>TabProd[[#This Row],[Value]],TabProd[[#This Row],[Amount Charged]]-TabProd[[#This Row],[Value]],"") | N5: 5189 | P5: 1445 | Q5: 506.6 | R5: 45974 | S5: =IF(R5="","",R5-J5) -> 41 | T5: 903 | U5: -149307.4 | V5: 46339 | W5: =IF(V5="","",V5-J5) -> 406 | X5: =TabProd[[#This Row],[Value]]-TabProd[[#This Row],[InvoiceTotal Value]]-TabProd[[#This Row],[Rental Equipment Invoice Value]]+AR4 -> 0 | AA5: =SUM(Y5:Z5) -> 0 | AD5: 164.81 | AE5: 341.79 | AG5: -149307.4 | AP5: =SUM(AB5:AO5) -> -148800.8 | AQ5: =IF(TabProd[[#This Row],[Total Daily]]=0,"",TabProd[[#This Row],[Total]]/TabProd[[#This Row],[Total Daily]])
A6: 46023 | B6: F | D6: 3445 | E6: Engineering | F6: Helix | G6: SH2 | H6: 4912 | I6: 45931 | J6: 45961 | K6: -22800 | L6: =SUM(TabProd[[#This Row],[Personal]:[Engineering]]) -> -22800 | M6: =IF(TabProd[[#This Row],[Amount Charged]]<>TabProd[[#This Row],[Value]],TabProd[[#This Row],[Amount Charged]]-TabProd[[#This Row],[Value]],"") | N6: 5154 | P6: 0 | Q6: -22800 | S6: =IF(R6="","",R6-J6) | W6: =IF(V6="","",V6-J6) | X6: =TabProd[[#This Row],[Value]]-TabProd[[#This Row],[InvoiceTotal Value]]-TabProd[[#This Row],[Rental Equipment Invoice Value]]+AR6 -> 0 | AA6: =SUM(Y6:Z6) -> 0 | AO6: -22800 | AP6: =SUM(AB6:AO6) -> -22800 | AQ6: =IF(TabProd[[#This Row],[Total Daily]]=0,"",TabProd[[#This Row],[Total]]/TabProd[[#This Row],[Total Daily]])
A7: 46023 | B7: F | D7: 3292 | E7: Inspection Contract - Fixed Team | F7: Helix | G7: SH1 | H7: 3970 | I7: 45933 | J7: 45961 | K7: 30438.26 | L7: =SUM(TabProd[[#This Row],[Personal]:[Engineering]]) -> 30438.26 | M7: =IF(TabProd[[#This Row],[Amount Charged]]<>TabProd[[#This Row],[Value]],TabProd[[#This Row],[Amount Charged]]-TabProd[[#This Row],[Value]],"") | N7: 5177 | P7: 1448 | Q7: 30438.26 | R7: 45974 | S7: =IF(R7="","",R7-J7) -> 13 | T7: 905 | U7: 0 | V7: 45974 | W7: =IF(V7="","",V7-J7) -> 13 | X7: =TabProd[[#This Row],[Value]]-TabProd[[#This Row],[InvoiceTotal Value]]-TabProd[[#This Row],[Rental Equipment Invoice Value]]+AR7 -> 0 | AA7: =SUM(Y7:Z7) -> 0 | AB7: 23768.52 | AE7: 538.2 | AL7: 6131.54 | AP7: =SUM(AB7:AO7) -> 30438.26 | AQ7: =IF(TabProd[[#This Row],[Total Daily]]=0,"",TabProd[[#This Row],[Total]]/TabProd[[#This Row],[Total Daily]])
A8: 46023 | B8: F | D8: 3045 | E8: Maintenance Contract - Variable | F8: Helix | G8: SH1 | H8: 3983 | I8: 45940 | J8: 45954 | K8: 864 | L8: =SUM(TabProd[[#This Row],[Personal]:[Engineering]]) -> 864 | M8: =IF(TabProd[[#This Row],[Amount Charged]]<>TabProd[[#This Row],[Value]],TabProd[[#This Row],[Amount Charged]]-TabProd[[#This Row],[Value]],"") | N8: 5204 | O8: 45965 | P8: 1447 | Q8: 864 | R8: 45974 | S8: =IF(R8="","",R8-J8) -> 20 | T8: 904 | U8: 0 | V8: 45974 | W8: =IF(V8="","",V8-J8) -> 20 | X8: =TabProd[[#This Row],[Value]]-TabProd[[#This Row],[InvoiceTotal Value]]-TabProd[[#This Row],[Rental Equipment Invoice Value]]+AR8 -> 0 | AA8: =SUM(Y8:Z8) -> 0 | AD8: 864 | AP8: =SUM(AB8:AO8) -> 864 | AQ8: =IF(TabProd[[#This Row],[Total Daily]]=0,"",TabProd[[#This Row],[Total]]/TabProd[[#This Row],[Total Daily]])
A9: 46023 | B9: F | D9: 3380 | E9: Inspection Contract - Variable | F9: Modec | G9: MV-20 | H9: 4784 | I9: 45943 | J9: 45953 | K9: -4977.39 | L9: =SUM(TabProd[[#This Row],[Personal]:[Engineering]]) -> -4977.39 | M9: =IF(TabProd[[#This Row],[Amount Charged]]<>TabProd[[#This Row],[Value]],TabProd[[#This Row],[Amount Charged]]-TabProd[[#This Row],[Value]],"") | N9: 5183 | O9: 46028 | P9: 1620 | Q9: -4977.39 | R9: 46041 | S9: =IF(R9="","",R9-J9) -> 88 | W9: =IF(V9="","",V9-J9) | X9: =TabProd[[#This Row],[Value]]-TabProd[[#This Row],[InvoiceTotal Value]]-TabProd[[#This Row],[Rental Equipment Invoice Value]]+AR9 -> 0 | Y9: -1 | AA9: =SUM(Y9:Z9) -> -1 | AB9: -4977.39 | AP9: =SUM(AB9:AO9) -> -4977.39 | AQ9: =IF(TabProd[[#This Row],[Total Daily]]=0,"",TabProd[[#This Row],[Total]]/TabProd[[#This Row],[Total Daily]]) -> 4977.39
A10: 46023 | B10: F | D10: 3580 | E10: Inspection Contract - Variable | F10: SEA1 | G10: SH1 | H10: 5158 | I10: 45943 | J10: 45954 | K10: -78483.6 | L10: =SUM(TabProd[[#This Row],[Personal]:[Engineering]]) -> -78483.6 | M10: =IF(TabProd[[#This Row],[Amount Charged]]<>TabProd[[#This Row],[Value]],TabProd[[#This Row],[Amount Charged]]-TabProd[[#This Row],[Value]],"") | N10: 5172 | P10: 0 | Q10: -78483.6 | S10: =IF(R10="","",R10-J10) | W10: =IF(V10="","",V10-J10) | X10: =TabProd[[#This Row],[Value]]-TabProd[[#This Row],[InvoiceTotal Value]]-TabProd[[#This Row],[Rental Equipment Invoice Value]]+AR9 -> 0 | Y10: -30 | AA10: =SUM(Y10:Z10) -> -30 | AB10: -62856 | AD10: -2160 | AG10: -10281.6 | AH10: -3186 | AP10: =SUM(AB10:AO10) -> -78483.6 | AQ10: =IF(TabProd[[#This Row],[Total Daily]]=0,"",TabProd[[#This Row],[Total]]/TabProd[[#This Row],[Total Daily]]) -> 2616.12
A11: 46023 | B11: F | D11: 3606 | E11: Equipment Rental | F11: Helix | G11: SH1 | H11: 5228 | I11: 45960 | J11: 45969 | K11: 27319.68 | L11: =SUM(TabProd[[#This Row],[Personal]:[Engineering]]) -> 27319.68 | M11: =IF(TabProd[[#This Row],[Amount Charged]]<>TabProd[[#This Row],[Value]],TabProd[[#This Row],[Amount Charged]]-TabProd[[#This Row],[Value]],"") | N11: 5237 | O11: 46079 | S11: =IF(R11="","",R11-J11) | T11: 1109 | U11: 27319.68 | V11: 46099 | W11: =IF(V11="","",V11-J11) -> 130 | X11: =TabProd[[#This Row],[Value]]-TabProd[[#This Row],[InvoiceTotal Value]]-TabProd[[#This Row],[Rental Equipment Invoice Value]]+AR8 -> -3.6379788e-12 | AA11: =SUM(Y11:Z11) -> 0 | AG11: 27319.68 | AP11: =SUM(AB11:AO11) -> 27319.68 | AQ11: =IF(TabProd[[#This Row],[Total Daily]]=0,"",TabProd[[#This Row],[Total]]/TabProd[[#This Row],[Total Daily]])
A12: 46054 | B12: F | D12: 3608 | E12: Inspection Contract - Variable | F12: Helix | G12: SH1 | H12: 5202 | I12: 45960 | J12: 46054 | K12: 43152 | L12: =SUM(TabProd[[#This Row],[Personal]:[Engineering]]) -> 43152 | M12: =IF(TabProd[[#This Row],[Amount Charged]]<>TabProd[[#This Row],[Value]],TabProd[[#This Row],[Amount Charged]]-TabProd[[#This Row],[Value]],"") | N12: 5299 | O12: 46066 | P12: 1743 | Q12: 43152 | R12: 46084 | S12: =IF(R12="","",R12-J12) -> 30 | W12: =IF(V12="","",V12-J12) | X12: =TabProd[[#This Row],[Value]]-TabProd[[#This Row],[InvoiceTotal Value]]-TabProd[[#This Row],[Rental Equipment Invoice Value]]+AR11 -> 0 | AA12: =SUM(Y12:Z12) -> 0 | AN12: 405 | AO12: 42747 | AP12: =SUM(AB12:AO12) -> 43152 | AQ12: =IF(TabProd[[#This Row],[Total Daily]]=0,"",TabProd[[#This Row],[Total]]/TabProd[[#This Row],[Total Daily]])
A13: 46082 | B13: F | D13: 3606 | E13: Equipment Rental | F13: Helix | G13: SH1 | H13: 5228 | I13: 45960 | J13: 45969 | K13: -33827.76 | L13: =SUM(TabProd[[#This Row],[Personal]:[Engineering]]) -> -33827.76 | M13: =IF(TabProd[[#This Row],[Amount Charged]]<>TabProd[[#This Row],[Value]],TabProd[[#This Row],[Amount Charged]]-TabProd[[#This Row],[Value]],"") | N13: 5237 | O13: 46079 | S13: =IF(R13="","",R13-J13) | T13: 1109 | U13: -33827.76 | V13: 46099 | W13: =IF(V13="","",V13-J13) -> 130 | X13: =TabProd[[#This Row],[Value]]-TabProd[[#This Row],[InvoiceTotal Value]]-TabProd[[#This Row],[Rental Equipment Invoice Value]]+AR13 -> 0 | AA13: =SUM(Y13:Z13) -> 0 | AG13: -33827.76 | AP13: =SUM(AB13:AO13) -> -33827.76 | AQ13: =IF(TabProd[[#This Row],[Total Daily]]=0,"",TabProd[[#This Row],[Total]]/TabProd[[#This Row],[Total Daily]])
A14: 46054 | B14: F | D14: 3359 | E14: Inspection Spot | F14: Seadrill | G14: West Jupiter | H14: 4730 | I14: 45962 | J14: 45991 | K14: -83864 | L14: =SUM(TabProd[[#This Row],[Personal]:[Engineering]]) -> -83864 | M14: =IF(TabProd[[#This Row],[Amount Charged]]<>TabProd[[#This Row],[Value]],TabProd[[#This Row],[Amount Charged]]-TabProd[[#This Row],[Value]],"") | N14: 5244 | O14: 45992 | P14: 19 | Q14: -83864 | R14: 46078 | S14: =IF(R14="","",R14-J14) -> 87 | T14: 2556 | V14: 46078 | W14: =IF(V14="","",V14-J14) -> 87 | X14: =TabProd[[#This Row],[Value]]-TabProd[[#This Row],[InvoiceTotal Value]]-TabProd[[#This Row],[Rental Equipment Invoice Value]]+AR14 -> 0 | AA14: =SUM(Y14:Z14) -> 0 | AM14: -83864 | AP14: =SUM(AB14:AO14) -> -83864 | AQ14: =IF(TabProd[[#This Row],[Total Daily]]=0,"",TabProd[[#This Row],[Total]]/TabProd[[#This Row],[Total Daily]])
A15: 46023 | B15: F | D15: 3292 | E15: Inspection Contract - Fixed Team | F15: Helix | G15: SH1 | H15: 3970 | I15: 45969 | J15: 45975 | K15: -45179.75 | L15: =SUM(TabProd[[#This Row],[Personal]:[Engineering]]) -> -45179.75 | M15: =IF(TabProd[[#This Row],[Amount Charged]]<>TabProd[[#This Row],[Value]],TabProd[[#This Row],[Amount Charged]]-TabProd[[#This Row],[Value]],"") | N15: 5256 | O15: 46001 | P15: 1623 | Q15: -27107.85 | R15: 46041 | S15: =IF(R15="","",R15-J15) -> 66 | T15: 1004 | U15: -18071.9 | V15: 46041 | W15: =IF(V15="","",V15-J15) -> 66 | X15: =TabProd[[#This Row],[Value]]-TabProd[[#This Row],[InvoiceTotal Value]]-TabProd[[#This Row],[Rental Equipment Invoice Value]]+AR15 -> 0 | Y15: -6 | AA15: =SUM(Y15:Z15) -> -6 | AB15: -27107.85 | AG15: -18071.9 | AP15: =SUM(AB15:AO15) -> -45179.75 | AQ15: =IF(TabProd[[#This Row],[Total Daily]]=0,"",TabProd[[#This Row],[Total]]/TabProd[[#This Row],[Total Daily]]) -> 7529.9583
A16: 46082 | B16: F | D16: 3572 | E16: Maintenance Spot | F16: Archer | G16: Peregrino Alpha | H16: 5145 | I16: 45973 | J16: 45991 | K16: 870.16 | L16: =SUM(TabProd[[#This Row],[Personal]:[Engineering]]) -> 870.16 | M16: =IF(TabProd[[#This Row],[Amount Charged]]<>TabProd[[#This Row],[Value]],TabProd[[#This Row],[Amount Charged]]-TabProd[[#This Row],[Value]],"") | N16: 5249 | O16: 46021 | P16: 1781 | Q16: 870.16 | R16: 46091 | S16: =IF(R16="","",R16-J16) -> 100 | W16: =IF(V16="","",V16-J16) | X16: =TabProd[[#This Row],[Value]]-TabProd[[#This Row],[InvoiceTotal Value]]-TabProd[[#This Row],[Rental Equipment Invoice Value]]+AR16 -> -1.1368684e-13 | Y16: -7 | AA16: =SUM(Y16:Z16) -> -7 | AB16: -1881.08 | AD16: 2751.24 | AP16: =SUM(AB16:AO16) -> 870.16 | AQ16: =IF(TabProd[[#This Row],[Total Daily]]=0,"",TabProd[[#This Row],[Total]]/TabProd[[#This Row],[Total Daily]]) -> -124.30857
A17: 46054 | B17: F | D17: 3593 | E17: Inspection Spot | F17: Modec | G17: MV-18 | H17: 5154 | I17: 45977 | J17: 45983 | K17: -4996.4 | L17: =SUM(TabProd[[#This Row],[Personal]:[Engineering]]) -> -4996.4 | M17: =IF(TabProd[[#This Row],[Amount Charged]]<>TabProd[[#This Row],[Value]],TabProd[[#This Row],[Amount Charged]]-TabProd[[#This Row],[Value]],"") | N17: 5270 | O17: 46020 | P17: 2 | Q17: -4996.4 | R17: 46028 | S17: =IF(R17="","",R17-J17) -> 45 | W17: =IF(V17="","",V17-J17) | X17: =TabProd[[#This Row],[Value]]-TabProd[[#This Row],[InvoiceTotal Value]]-TabProd[[#This Row],[Rental Equipment Invoice Value]]+AR16 -> 0 | AA17: =SUM(Y17:Z17) -> 0 | AG17: -12726 | AH17: 7729.6 | AP17: =SUM(AB17:AO17) -> -4996.4 | AQ17: =IF(TabProd[[#This Row],[Total Daily]]=0,"",TabProd[[#This Row],[Total]]/TabProd[[#This Row],[Total Daily]])
A18: 46023 | B18: F | D18: 3616 | E18: Inspection Spot | F18: Modec | G18: MV-18 | H18: 5233 | I18: 45980 | J18: 46355 | K18: -11538.3 | L18: =SUM(TabProd[[#This Row],[Personal]:[Engineering]]) -> -11538.3 | M18: =IF(TabProd[[#This Row],[Amount Charged]]<>TabProd[[#This Row],[Value]],TabProd[[#This Row],[Amount Charged]]-TabProd[[#This Row],[Value]],"") | N18: 5268 | O18: 46020 | P18: 1579 | Q18: -10581.5 | R18: 46034 | S18: =IF(R18="","",R18-J18) -> -321 | T18: 988 | U18: -956.8 | V18: 46034 | W18: =IF(V18="","",V18-J18) -> -321 | X18: =TabProd[[#This Row],[Value]]-TabProd[[#This Row],[InvoiceTotal Value]]-TabProd[[#This Row],[Rental Equipment Invoice Value]]+AR17 -> -1.8189894e-12 | Y18: -4 | Z18: -2 | AA18: =SUM(Y18:Z18) -> -6 | AB18: -8574.4 | AC18: -2005.6 | AE18: -1.5 | AG18: -956.8 | AP18: =SUM(AB18:AO18) -> -11538.3 | AQ18: =IF(TabProd[[#This Row],[Total Daily]]=0,"",TabProd[[#This Row],[Total]]/TabProd[[#This Row],[Total Daily]]) -> 1923.05
A19: 46023 | B19: F | D19: 3427 | E19: Maintenance Contract - Variable | F19: Foresea | G19: ODN I | H19: 4892 | I19: 45984 | J19: 46005 | K19: -3775.38 | L19: =SUM(TabProd[[#This Row],[Personal]:[Engineering]]) -> -3775.38 | M19: =IF(TabProd[[#This Row],[Amount Charged]]<>TabProd[[#This Row],[Value]],TabProd[[#This Row],[Amount Charged]]-TabProd[[#This Row],[Value]],"") | N19: 5272-5361 | O19: 46028 | P19: 1574 | Q19: 0 | R19: 46031 | S19: =IF(R19="","",R19-J19) -> 26 | T19: 983-984 | U19: -3775.38 | V19: 46031 | W19: =IF(V19="","",V19-J19) -> 26 | X19: =TabProd[[#This Row],[Value]]-TabProd[[#This Row],[InvoiceTotal Value]]-TabProd[[#This Row],[Rental Equipment Invoice Value]]+AR19 -> 0 | AA19: =SUM(Y19:Z19) -> 0 | AG19: -3775.38 | AP19: =SUM(AB19:AO19) -> -3775.38 | AQ19: =IF(TabProd[[#This Row],[Total Daily]]=0,"",TabProd[[#This Row],[Total]]/TabProd[[#This Row],[Total Daily]])
A20: 46023 | B20: F | D20: 3545 | E20: Inspection Contract - Variable | F20: Constellation | G20: Gold Star | H20: 5088 | I20: 45985 | J20: 46034 | K20: 50168 | L20: =SUM(TabProd[[#This Row],[Personal]:[Engineering]]) -> 50168 | M20: =IF(TabProd[[#This Row],[Amount Charged]]<>TabProd[[#This Row],[Value]],TabProd[[#This Row],[Amount Charged]]-TabProd[[#This Row],[Value]],"") | N20: 5388-5513-5514 | O20: 46035 | S20: =IF(R20="","",R20-J20) | T20: 1059-1060-1066 | U20: 50168 | V20: 46072 | W20: =IF(V20="","",V20-J20) -> 38 | X20: =TabProd[[#This Row],[Value]]-TabProd[[#This Row],[InvoiceTotal Value]]-TabProd[[#This Row],[Rental Equipment Invoice Value]]+AR19 -> 0 | AA20: =SUM(Y20:Z20) -> 0 | AG20: 49000 | AH20: 1168 | AP20: =SUM(AB20:AO20) -> 50168 | AQ20: =IF(TabProd[[#This Row],[Total Daily]]=0,"",TabProd[[#This Row],[Total]]/TabProd[[#This Row],[Total Daily]])
A21: 46023 | B21: F | D21: 3563 | E21: Inspection Spot | F21: Technip | G21: Skandi Vitoria | H21: 5031 | I21: 45986 | J21: 46031 | K21: 25322.08 | L21: =SUM(TabProd[[#This Row],[Personal]:[Engineering]]) -> 25322.08 | M21: =IF(TabProd[[#This Row],[Amount Charged]]<>TabProd[[#This Row],[Value]],TabProd[[#This Row],[Amount Charged]]-TabProd[[#This Row],[Value]],"") | N21: 5434 | O21: 46043 | S21: =IF(R21="","",R21-J21) | T21: 2555 | U21: 25322.08 | V21: 46076 | W21: =IF(V21="","",V21-J21) -> 45 | X21: =TabProd[[#This Row],[Value]]-TabProd[[#This Row],[InvoiceTotal Value]]-TabProd[[#This Row],[Rental Equipment Invoice Value]]+AR20 -> 0 | AA21: =SUM(Y21:Z21) -> 0 | AG21: 25322.08 | AP21: =SUM(AB21:AO21) -> 25322.08 | AQ21: =IF(TabProd[[#This Row],[Total Daily]]=0,"",TabProd[[#This Row],[Total]]/TabProd[[#This Row],[Total Daily]])
A22: 46082 | B22: F | D22: 3535 | E22: Inspection Spot | F22: Trident | G22: P-65 | H22: 5008 | I22: 45988 | J22: 46001 | K22: 1094.8 | L22: =SUM(TabProd[[#This Row],[Personal]:[Engineering]]) -> 1094.8 | M22: =IF(TabProd[[#This Row],[Amount Charged]]<>TabProd[[#This Row],[Value]],TabProd[[#This Row],[Amount Charged]]-TabProd[[#This Row],[Value]],"") | N22: 5276-5560 | O22: 46385 | P22: 1818-1823 | Q22: 1094.8 | R22: 46104 | S22: =IF(R22="","",R22-J22) -> 103 | W22: =IF(V22="","",V22-J22) | X22: =TabProd[[#This Row],[Value]]-TabProd[[#This Row],[InvoiceTotal Value]]-TabProd[[#This Row],[Rental Equipment Invoice Value]]+AR22 -> 0 | AA22: =SUM(Y22:Z22) -> 0 | AM22: 1094.8 | AP22: =SUM(AB22:AO22) -> 1094.8 | AQ22: =IF(TabProd[[#This Row],[Total Daily]]=0,"",TabProd[[#This Row],[Total]]/TabProd[[#This Row],[Total Daily]])
A23: 46054 | B23: F | D23: 3563 | E23: Inspection Spot | F23: Technip | G23: Skandi Vitoria | H23: 5031 | I23: 45990 | J23: 46004 | K23: -25697.08 | L23: =SUM(TabProd[[#This Row],[Personal]:[Engineering]]) -> -25697.08 | M23: =IF(TabProd[[#This Row],[Amount Charged]]<>TabProd[[#This Row],[Value]],TabProd[[#This Row],[Amount Charged]]-TabProd[[#This Row],[Value]],"") | N23: 5281-5559 | O23: 46034 | P23: 23-28 | Q23: -2092.5 | R23: 46104 | S23: =IF(R23="","",R23-J23) -> 100 | T23: 2559 | U23: -23604.58 | V23: 46179 | W23: =IF(V23="","",V23-J23) -> 175 | X23: =TabProd[[#This Row],[Value]]-TabProd[[#This Row],[InvoiceTotal Value]]-TabProd[[#This Row],[Rental Equipment Invoice Value]]+AR23 -> 0 | AA23: =SUM(Y23:Z23) -> 0 | AG23: -25322.08 | AN23: -375 | AP23: =SUM(AB23:AO23) -> -25697.08 | AQ23: =IF(TabProd[[#This Row],[Total Daily]]=0,"",TabProd[[#This Row],[Total]]/TabProd[[#This Row],[Total Daily]])
A24: 46023 | B24: F | D24: 3341 | E24: Inspection Spot | F24: Seadrill | G24: West Tellus | H24: 4693 | I24: 45992 | J24: 46022 | K24: -9000 | L24: =SUM(TabProd[[#This Row],[Personal]:[Engineering]]) -> -9000 | M24: =IF(TabProd[[#This Row],[Amount Charged]]<>TabProd[[#This Row],[Value]],TabProd[[#This Row],[Amount Charged]]-TabProd[[#This Row],[Value]],"") | N24: 5312 | O24: 46024 | P24: 1655 | Q24: -9000 | R24: 46048 | S24: =IF(R24="","",R24-J24) -> 26 | T24: 1017 | U24: 0 | V24: 46048 | W24: =IF(V24="","",V24-J24) -> 26 | X24: =TabProd[[#This Row],[Value]]-TabProd[[#This Row],[InvoiceTotal Value]]-TabProd[[#This Row],[Rental Equipment Invoice Value]]+AR24 -> 0 | AA24: =SUM(Y24:Z24) -> 0 | AM24: -9000 | AP24: =SUM(AB24:AO24) -> -9000 | AQ24: =IF(TabProd[[#This Row],[Total Daily]]=0,"",TabProd[[#This Row],[Total]]/TabProd[[#This Row],[Total Daily]])
A25: 46023 | B25: F | D25: 3300 | E25: Inspection Contract - Fixed Team | F25: Transocean | G25: Corcovado | H25: 1877 | I25: 45992 | J25: 46022 | K25: 525.5 | L25: =SUM(TabProd[[#This Row],[Personal]:[Engineering]]) -> 525.5 | M25: =IF(TabProd[[#This Row],[Amount Charged]]<>TabProd[[#This Row],[Value]],TabProd[[#This Row],[Amount Charged]]-TabProd[[#This Row],[Value]],"") | N25: 5403 | O25: 46036 | P25: 1614 | Q25: 525.5 | R25: 46038 | S25: =IF(R25="","",R25-J25) -> 16 | W25: =IF(V25="","",V25-J25) | X25: =TabProd[[#This Row],[Value]]-TabProd[[#This Row],[InvoiceTotal Value]]-TabProd[[#This Row],[Rental Equipment Invoice Value]]+AR25 -> 0 | AA25: =SUM(Y25:Z25) -> 0 | AL25: 525.5 | AP25: =SUM(AB25:AO25) -> 525.5 | AQ25: =IF(TabProd[[#This Row],[Total Daily]]=0,"",TabProd[[#This Row],[Total]]/TabProd[[#This Row],[Total Daily]])
A26: 46023 | B26: F | D26: 3627 | E26: Inspection Contract - Variable | F26: Transocean | G26: KG2 | H26: 5249 | I26: 45996 | J26: 46011 | K26: 3079.23 | L26: =SUM(TabProd[[#This Row],[Personal]:[Engineering]]) -> 3079.23 | M26: =IF(TabProd[[#This Row],[Amount Charged]]<>TabProd[[#This Row],[Value]],TabProd[[#This Row],[Amount Charged]]-TabProd[[#This Row],[Value]],"") | N26: 5320 | O26: 46036 | P26: 1628 | Q26: 967.7 | R26: 46041 | S26: =IF(R26="","",R26-J26) -> 30 | T26: 1006 | U26: 2111.53 | V26: 46041 | W26: =IF(V26="","",V26-J26) -> 30 | X26: =TabProd[[#This Row],[Value]]-TabProd[[#This Row],[InvoiceTotal Value]]-TabProd[[#This Row],[Rental Equipment Invoice Value]]+AR25 -> 4.5474735e-13 | AA26: =SUM(Y26:Z26) -> 0 | AB26: 967.7 | AG26: 682.08 | AH26: 1429.45 | AP26: =SUM(AB26:AO26) -> 3079.23 | AQ26: =IF(TabProd[[#This Row],[Total Daily]]=0,"",TabProd[[#This Row],[Total]]/TabProd[[#This Row],[Total Daily]])
A27: 46023 | B27: F | D27: 3583 | E27: Inspection Contract - Variable | F27: Ventura | G27: DS Carolina | H27: 5137 | I27: 45999 | J27: 46013 | K27: 12008 | L27: =SUM(TabProd[[#This Row],[Personal]:[Engineering]]) -> 12008 | M27: =IF(TabProd[[#This Row],[Amount Charged]]<>TabProd[[#This Row],[Value]],TabProd[[#This Row],[Amount Charged]]-TabProd[[#This Row],[Value]],"") | N27: 5343-5384 | O27: 46030 | P27: 1581-1604 | Q27: 12608 | R27: 46037 | S27: =IF(R27="","",R27-J27) -> 24 | T27: 991 | U27: -600 | V27: 46034 | W27: =IF(V27="","",V27-J27) -> 21 | X27: =TabProd[[#This Row],[Value]]-TabProd[[#This Row],[InvoiceTotal Value]]-TabProd[[#This Row],[Rental Equipment Invoice Value]]+AR26 -> 0 | Y27: 6 | AA27: =SUM(Y27:Z27) -> 6 | AB27: 19820 | AD27: 1160 | AG27: -600 | AM27: -8372 | AP27: =SUM(AB27:AO27) -> 12008 | AQ27: =IF(TabProd[[#This Row],[Total Daily]]=0,"",TabProd[[#This Row],[Total]]/TabProd[[#This Row],[Total Daily]]) -> 2001.3333
A28: 46054 | B28: F | D28: 3607 | E28: Inspection Spot | F28: Technip | G28: Skandi Buzios | H28: 5031 | I28: 45999 | J28: 46010 | K28: -9439.83 | L28: =SUM(TabProd[[#This Row],[Personal]:[Engineering]]) -> -9439.83 | M28: =IF(TabProd[[#This Row],[Amount Charged]]<>TabProd[[#This Row],[Value]],TabProd[[#This Row],[Amount Charged]]-TabProd[[#This Row],[Value]],"") | N28: 5282 | O28: 46021 | P28: 1732 | Q28: -9439.83 | R28: 46073 | S28: =IF(R28="","",R28-J28) -> 63 | T28: 1068 | U28: 0 | V28: 46073 | W28: =IF(V28="","",V28-J28) -> 63 | X28: =TabProd[[#This Row],[Value]]-TabProd[[#This Row],[InvoiceTotal Value]]-TabProd[[#This Row],[Rental Equipment Invoice Value]]+AR27 -> 0 | AA28: =SUM(Y28:Z28) -> 0 | AB28: -4087.27 | AD28: 400 | AE28: -5752.56 | AP28: =SUM(AB28:AO28) -> -9439.83 | AQ28: =IF(TabProd[[#This Row],[Total Daily]]=0,"",TabProd[[#This Row],[Total]]/TabProd[[#This Row],[Total Daily]])
A29: 46023 | B29: F | D29: 3611 | E29: Inspection Contract - Variable | F29: Ventura | G29: DS Carolina | I29: 46002 | J29: 46005 | K29: 10320 | L29: =SUM(TabProd[[#This Row],[Personal]:[Engineering]]) -> 10320 | M29: =IF(TabProd[[#This Row],[Amount Charged]]<>TabProd[[#This Row],[Value]],TabProd[[#This Row],[Amount Charged]]-TabProd[[#This Row],[Value]],"") | N29: 5383 | O29: 46038 | P29: 1645 | Q29: 8720 | R29: 46044 | S29: =IF(R29="","",R29-J29) -> 39 | T29: 1015 | U29: 1600 | V29: 46044 | W29: =IF(V29="","",V29-J29) -> 39 | X29: =TabProd[[#This Row],[Value]]-TabProd[[#This Row],[InvoiceTotal Value]]-TabProd[[#This Row],[Rental Equipment Invoice Value]]+AR28 -> 0 | Y29: 4 | AA29: =SUM(Y29:Z29) -> 4 | AB29: 8720 | AG29: 1600 | AP29: =SUM(AB29:AO29) -> 10320 | AQ29: =IF(TabProd[[#This Row],[Total Daily]]=0,"",TabProd[[#This Row],[Total]]/TabProd[[#This Row],[Total Daily]]) -> 2580
A30: 46113 | D30: 3478 | E30: Maintenance Contract - Variable | F30: Foresea | G30: Norbe 9 | H30: 4984 | I30: 46002 | J30: 46031 | K30: 282203.41 | L30: =SUM(TabProd[[#This Row],[Personal]:[Engineering]]) -> 282203.41 | M30: =IF(TabProd[[#This Row],[Amount Charged]]<>TabProd[[#This Row],[Value]],TabProd[[#This Row],[Amount Charged]]-TabProd[[#This Row],[Value]],"") | N30: 5300 | O30: 46183 | P30: 2045 | Q30: 102100.81 | R30: 46192 | S30: =IF(R30="","",R30-J30) -> 161 | T30: 1261 | U30: 180102.6 | V30: 46192 | W30: =IF(V30="","",V30-J30) -> 161 | X30: =TabProd[[#This Row],[Value]]-TabProd[[#This Row],[InvoiceTotal Value]]-TabProd[[#This Row],[Rental Equipment Invoice Value]]+AR29 -> 2.910383e-11 | Y30: 1 | AA30: =SUM(Y30:Z30) -> 1 | AB30: 79712.78 | AC30: 22388.03 | AG30: 180102.6 | AP30: =SUM(AB30:AO30) -> 282203.41 | AQ30: =IF(TabProd[[#This Row],[Total Daily]]=0,"",TabProd[[#This Row],[Total]]/TabProd[[#This Row],[Total Daily]]) -> 282203.41
A31: 46174 | D31: 3478 | E31: Maintenance Contract - Variable | F31: Foresea | G31: Norbe 9 | H31: 4984 | I31: 46002 | J31: 46031 | K31: 14274.08 | L31: =SUM(TabProd[[#This Row],[Personal]:[Engineering]]) -> 14274.08 | M31: =IF(TabProd[[#This Row],[Amount Charged]]<>TabProd[[#This Row],[Value]],TabProd[[#This Row],[Amount Charged]]-TabProd[[#This Row],[Value]],"") | N31: 5300 | O31: 46183 | P31: 2045 | Q31: 5163.98 | R31: 46192 | S31: =IF(R31="","",R31-J31) -> 161 | T31: 1261 | U31: 9110.1 | V31: 46192 | W31: =IF(V31="","",V31-J31) -> 161 | X31: =TabProd[[#This Row],[Value]]-TabProd[[#This Row],[InvoiceTotal Value]]-TabProd[[#This Row],[Rental Equipment Invoice Value]]+AR31 -> 7.2759576e-12 | Y31: 30 | Z31: 17 | AA31: =SUM(Y31:Z31) -> 47 | AB31: 4031.63 | AC31: 1132.35 | AG31: 9110.1 | AP31: =SUM(AB31:AO31) -> 14274.08 | AQ31: =IF(TabProd[[#This Row],[Total Daily]]=0,"",TabProd[[#This Row],[Total]]/TabProd[[#This Row],[Total Daily]]) -> 303.70383
A32: 46023 | B32: F | D32: 3619 | E32: Inspection Contract - Variable | F32: Transocean | G32: Orion | H32: 5243 | I32: 46002 | J32: 46011 | K32: 1068.14 | L32: =SUM(TabProd[[#This Row],[Personal]:[Engineering]]) -> 1068.14 | M32: =IF(TabProd[[#This Row],[Amount Charged]]<>TabProd[[#This Row],[Value]],TabProd[[#This Row],[Amount Charged]]-TabProd[[#This Row],[Value]],"") | N32: 5347 | O32: 46035 | P32: 1611 | Q32: 1068.14 | R32: 46037 | S32: =IF(R32="","",R32-J32) -> 26 | T32: 1001 | U32: 0 | V32: 46037 | W32: =IF(V32="","",V32-J32) -> 26 | X32: =TabProd[[#This Row],[Value]]-TabProd[[#This Row],[InvoiceTotal Value]]-TabProd[[#This Row],[Rental Equipment Invoice Value]]+AR31 -> -4.5474735e-12 | AA32: =SUM(Y32:Z32) -> 0 | AB32: 1068.13 | AE32: 0.01 | AP32: =SUM(AB32:AO32) -> 1068.14 | AQ32: =IF(TabProd[[#This Row],[Total Daily]]=0,"",TabProd[[#This Row],[Total]]/TabProd[[#This Row],[Total Daily]])
A33: 46023 | B33: F | D33: 3541 | E33: Inspection Contract - Variable | F33: Transocean | G33: Corcovado | H33: 4931 | I33: 46008 | J33: 46021 | K33: -12789 | L33: =SUM(TabProd[[#This Row],[Personal]:[Engineering]]) -> -12789 | M33: =IF(TabProd[[#This Row],[Amount Charged]]<>TabProd[[#This Row],[Value]],TabProd[[#This Row],[Amount Charged]]-TabProd[[#This Row],[Value]],"") | N33: 5377 | O33: 46030 | S33: =IF(R33="","",R33-J33) | T33: 1007 | U33: -12789 | V33: 46041 | W33: =IF(V33="","",V33-J33) -> 20 | X33: =TabProd[[#This Row],[Value]]-TabProd[[#This Row],[InvoiceTotal Value]]-TabProd[[#This Row],[Rental Equipment Invoice Value]]+AR32 -> 0 | AA33: =SUM(Y33:Z33) -> 0 | AG33: -12789 | AP33: =SUM(AB33:AO33) -> -12789 | AQ33: =IF(TabProd[[#This Row],[Total Daily]]=0,"",TabProd[[#This Row],[Total]]/TabProd[[#This Row],[Total Daily]])
A34: 46082 | B34: F | D34: 3599 | E34: Inspection Contract - Variable | F34: Constellation | G34: Amaralina Star | H34: 4854 | I34: 46010 | J34: 46074 | K34: 173163.8 | L34: =SUM(TabProd[[#This Row],[Personal]:[Engineering]]) -> 173163.8 | M34: =IF(TabProd[[#This Row],[Amount Charged]]<>TabProd[[#This Row],[Value]],TabProd[[#This Row],[Amount Charged]]-TabProd[[#This Row],[Value]],"") | N34: 5572 | S34: =IF(R34="","",R34-J34) | T34: 1115 | U34: 173163.8 | V34: 46101 | W34: =IF(V34="","",V34-J34) -> 27 | X34: =TabProd[[#This Row],[Value]]-TabProd[[#This Row],[InvoiceTotal Value]]-TabProd[[#This Row],[Rental Equipment Invoice Value]]+AR34 -> 0 | AA34: =SUM(Y34:Z34) -> 0 | AG34: 169943.8 | AH34: 3220 | AP34: =SUM(AB34:AO34) -> 173163.8 | AQ34: =IF(TabProd[[#This Row],[Total Daily]]=0,"",TabProd[[#This Row],[Total]]/TabProd[[#This Row],[Total Daily]])
A35: 46023 | B35: F | D35: 3415 | E35: Inspection Contract - Variable | F35: Modec | G35: FPSO Bacalhau | H35: 4874 | I35: 46011 | J35: 46024 | K35: 7822.04 | L35: =SUM(TabProd[[#This Row],[Personal]:[Engineering]]) -> 7822.04 | M35: =IF(TabProd[[#This Row],[Amount Charged]]<>TabProd[[#This Row],[Value]],TabProd[[#This Row],[Amount Charged]]-TabProd[[#This Row],[Value]],"") | N35: 5364 | O35: 46029 | P35: 1653 | Q35: 7822.04 | R35: 46045 | S35: =IF(R35="","",R35-J35) -> 21 | W35: =IF(V35="","",V35-J35) | X35: =TabProd[[#This Row],[Value]]-TabProd[[#This Row],[InvoiceTotal Value]]-TabProd[[#This Row],[Rental Equipment Invoice Value]]+AR35 -> 9.094947e-13 | Y35: 6 | AA35: =SUM(Y35:Z35) -> 6 | AB35: 7822.04 | AP35: =SUM(AB35:AO35) -> 7822.04 | AQ35: =IF(TabProd[[#This Row],[Total Daily]]=0,"",TabProd[[#This Row],[Total]]/TabProd[[#This Row],[Total Daily]]) -> 1303.6733
A36: 46082 | B36: F | D36: 3572 | E36: Maintenance Spot | F36: Archer | G36: Peregrino Alpha | H36: 5145 | I36: 46011 | J36: 46022 | K36: 219668.66 | L36: =SUM(TabProd[[#This Row],[Personal]:[Engineering]]) -> 219668.66 | M36: =IF(TabProd[[#This Row],[Amount Charged]]<>TabProd[[#This Row],[Value]],TabProd[[#This Row],[Amount Charged]]-TabProd[[#This Row],[Value]],"") | N36: 5351 | O36: 46021 | P36: 1782 | Q36: 219668.66 | R36: 46091 | S36: =IF(R36="","",R36-J36) -> 69 | W36: =IF(V36="","",V36-J36) | X36: =TabProd[[#This Row],[Value]]-TabProd[[#This Row],[InvoiceTotal Value]]-TabProd[[#This Row],[Rental Equipment Invoice Value]]+AR36 -> -2.910383e-11 | AA36: =SUM(Y36:Z36) -> 0 | AB36: 72340 | AD36: 1834.16 | AG36: 119525.7 | AH36: 3864.8 | AJ36: 22104 | AP36: =SUM(AB36:AO36) -> 219668.66 | AQ36: =IF(TabProd[[#This Row],[Total Daily]]=0,"",TabProd[[#This Row],[Total]]/TabProd[[#This Row],[Total Daily]])
A37: 46082 | B37: F | D37: 3636 | E37: Maintenance Spot | F37: Archer | G37: Peregrino Alpha | H37: 5278 | I37: 46011 | J37: 46022 | K37: -219668.66 | L37: =SUM(TabProd[[#This Row],[Personal]:[Engineering]]) -> -219668.66 | M37: =IF(TabProd[[#This Row],[Amount Charged]]<>TabProd[[#This Row],[Value]],TabProd[[#This Row],[Amount Charged]]-TabProd[[#This Row],[Value]],"") | N37: 5350 | O37: 46021 | P37: 1782 | Q37: -219668.66 | R37: 46091 | S37: =IF(R37="","",R37-J37) -> 69 | W37: =IF(V37="","",V37-J37) | X37: =TabProd[[#This Row],[Value]]-TabProd[[#This Row],[InvoiceTotal Value]]-TabProd[[#This Row],[Rental Equipment Invoice Value]]+AR37 -> 2.910383e-11 | AA37: =SUM(Y37:Z37) -> 0 | AB37: -72340 | AD37: -1834.16 | AG37: -119525.7 | AH37: -3864.8 | AJ37: -22104 | AP37: =SUM(AB37:AO37) -> -219668.66 | AQ37: =IF(TabProd[[#This Row],[Total Daily]]=0,"",TabProd[[#This Row],[Total]]/TabProd[[#This Row],[Total Daily]])
A38: 46023 | B38: F | D38: 3809 | E38: Inspection Contract - Fixed Team | F38: Constellation | G38: Admarine | H38: 5115 | I38: 46012 | J38: 46022 | K38: -0.16 | L38: =SUM(TabProd[[#This Row],[Personal]:[Engineering]]) -> -0.16 | M38: =IF(TabProd[[#This Row],[Amount Charged]]<>TabProd[[#This Row],[Value]],TabProd[[#This Row],[Amount Charged]]-TabProd[[#This Row],[Value]],"") | N38: 5376 | O38: 46029 | P38: 1616 | Q38: -0.16 | R38: 46038 | S38: =IF(R38="","",R38-J38) -> 16 | W38: =IF(V38="","",V38-J38) | X38: =TabProd[[#This Row],[Value]]-TabProd[[#This Row],[InvoiceTotal Value]]-TabProd[[#This Row],[Rental Equipment Invoice Value]]+AR35 -> 0 | AA38: =SUM(Y38:Z38) -> 0 | AM38: -0.16 | AP38: =SUM(AB38:AO38) -> -0.16 | AQ38: =IF(TabProd[[#This Row],[Total Daily]]=0,"",TabProd[[#This Row],[Total]]/TabProd[[#This Row],[Total Daily]])
A39: 46023 | B39: F | D39: 3500 | E39: Inspection Contract - Variable | F39: Modec | G39: MV-22 | H39: 5016 | I39: 46012 | J39: 46026 | K39: 14957.54 | L39: =SUM(TabProd[[#This Row],[Personal]:[Engineering]]) -> 14957.54 | M39: =IF(TabProd[[#This Row],[Amount Charged]]<>TabProd[[#This Row],[Value]],TabProd[[#This Row],[Amount Charged]]-TabProd[[#This Row],[Value]],"") | N39: 5367 | O39: 46029 | P39: 1590 | Q39: 14957.54 | R39: 46034 | S39: =IF(R39="","",R39-J39) -> 8 | W39: =IF(V39="","",V39-J39) | X39: =TabProd[[#This Row],[Value]]-TabProd[[#This Row],[InvoiceTotal Value]]-TabProd[[#This Row],[Rental Equipment Invoice Value]]+AR38 -> -5.4569682e-12 | Y39: 9 | AA39: =SUM(Y39:Z39) -> 9 | AB39: 15055.3 | AM39: -97.76 | AP39: =SUM(AB39:AO39) -> 14957.54 | AQ39: =IF(TabProd[[#This Row],[Total Daily]]=0,"",TabProd[[#This Row],[Total]]/TabProd[[#This Row],[Total Daily]]) -> 1661.9489
A40: 46023 | B40: F | D40: 3619 | E40: Inspection Contract - Variable | F40: Transocean | G40: Orion | H40: 5243 | I40: 46012 | J40: 46038 | K40: 41135.34 | L40: =SUM(TabProd[[#This Row],[Personal]:[Engineering]]) -> 41135.34 | M40: =IF(TabProd[[#This Row],[Amount Charged]]<>TabProd[[#This Row],[Value]],TabProd[[#This Row],[Amount Charged]]-TabProd[[#This Row],[Value]],"") | N40: 5416 | O40: 46049 | S40: =IF(R40="","",R40-J40) | T40: 1023 | U40: 41135.34 | V40: 46056 | W40: =IF(V40="","",V40-J40) -> 18 | X40: =TabProd[[#This Row],[Value]]-TabProd[[#This Row],[InvoiceTotal Value]]-TabProd[[#This Row],[Rental Equipment Invoice Value]]+AR39 -> 0 | AA40: =SUM(Y40:Z40) -> 0 | AG40: 39134.34 | AH40: 2001 | AP40: =SUM(AB40:AO40) -> 41135.34 | AQ40: =IF(TabProd[[#This Row],[Total Daily]]=0,"",TabProd[[#This Row],[Total]]/TabProd[[#This Row],[Total Daily]])
...

Sheet Planilha1
B1: Total Daily | C1: (Tudo)
C3: Rótulos de Coluna
C4: 45658 | D4: 45689 | E4: 45717 | F4: 45748 | G4: 45778 | H4: 45809 | I4: 45839 | J4: 45870 | K4: 45901 | L4: 45931 | M4: Total Geral
B5: Soma de Total | C5: 8162857.9 | D5: 11040023 | E5: 9503777 | F5: 7670252.1 | G5: 8360840.6 | H5: 8007506.7 | I5: 10241280 | J5: 12355008 | K5: 10410789 | L5: 13249252 | M5: 99001587
B7: Total Daily | C7: (Tudo)
B9: Soma de Total | C9: Rótulos de Coluna
B10: Rótulos de Linha | C10: 45658 | D10: 45689 | E10: 45717 | F10: 45748 | G10: 45778 | H10: 45809 | I10: 45839 | J10: 45870 | K10: 45901 | L10: 45931 | M10: Total Geral
B11: Engineering | G11: 99071 | H11: 218005 | I11: 311616 | J11: 376866 | K11: 203550 | L11: 409240 | M11: 1618348
B12: Equipment Rental | C12: 122519.06 | D12: 135038.28 | E12: 177870.84 | F12: 139228.43 | G12: 150764.34 | H12: 153932.9 | I12: 201974.08 | J12: 110764.1 | K12: 319698.7 | L12: -3632.72 | M12: 1508158
B13: Inspection Contract - Fixed Team | C13: 2527553.8 | D13: 2567526.7 | E13: 2552345.8 | F13: 2697320.1 | G13: 2634521.7 | H13: 2782488.6 | I13: 2892340.2 | J13: 2697071.4 | K13: 2352708.2 | L13: 2671161 | M13: 26375037
B14: Inspection Contract - Variable | C14: 1334866.5 | D14: 2677055.4 | E14: 2151275.9 | F14: 1509970.1 | G14: 1423202.2 | H14: 1211994.1 | I14: 2040312.8 | J14: 3786060.2 | K14: 3665965.3 | L14: 5588411.2 | M14: 25389114
B15: Inspection Spot | C15: 448449.54 | D15: 669372.35 | E15: 1503300.3 | F15: 1471788.9 | G15: 1778504.7 | H15: 1893352 | I15: 1706242.1 | J15: 2291293.9 | K15: 1597185.1 | L15: 1779596.5 | M15: 15139085
B16: Maintenance Contract - Variable | C16: 1419140.7 | D16: 3502008.9 | E16: 1969628.1 | F16: 1074008.6 | G16: 904611.12 | H16: 869121.47 | I16: 1791653.9 | J16: 2118005.3 | K16: 1764911.9 | L16: 1560597.5 | M16: 16973687
B17: Maintenance Spot | C17: 2310328.4 | D17: 1489021.7 | E17: 1149356.1 | F17: 777935.93 | G17: 1370165.7 | H17: 878612.64 | I17: 1297140.8 | J17: 974947.05 | K17: 506769.78 | L17: 1243878.8 | M17: 11998157
B18: Total Geral | C18: 8162857.9 | D18: 11040023 | E18: 9503777 | F18: 7670252.1 | G18: 8360840.6 | H18: 8007506.7 | I18: 10241280 | J18: 12355008 | K18: 10410789 | L18: 13249252 | M18: 99001587
B20: Inspeção | C20: =SUM(C13:C15) -> 4310869.8 | D20: =SUM(D13:D15) -> 5913954.4 | E20: =SUM(E13:E15) -> 6206922 | F20: =SUM(F13:F15) -> 5679079.1 | G20: =SUM(G13:G15) -> 5836228.5 | H20: =SUM(H13:H15) -> 5887834.7 | I20: =SUM(I13:I15) -> 6638895.1 | J20: =SUM(J13:J15) -> 8774425.5 | ... L20: =SUM(L13:L15) -> 10039169 | M20: =SUM(C20:L20) -> 66903236
B21: Manutenção | C21: =SUM(C16:C17) -> 3729469.1 | D21: =SUM(D16:D17) -> 4991030.5 | E21: =SUM(E16:E17) -> 3118984.1 | F21: =SUM(F16:F17) -> 1851944.5 | G21: =SUM(G16:G17) -> 2274776.8 | H21: =SUM(H16:H17) -> 1747734.1 | I21: =SUM(I16:I17) -> 3088794.7 | J21: =SUM(J16:J17) -> 3092952.4 | ... L21: =SUM(L16:L17) -> 2804476.3 | M21: =SUM(C21:L21) -> 28971844
B22: Engenharia | C22: =C11 -> 0 | D22: =D11 -> 0 | E22: =E11 -> 0 | F22: =F11 -> 0 | G22: =G11 -> 99071 | H22: =H11 -> 218005 | I22: =I11 -> 311616 | J22: =J11 -> 376866 | ... L22: =L11 -> 409240 | M22: =SUM(C22:L22) -> 1618348
B23: Outros | C23: =C18-C22-C21-C20 -> 122519.06 | D23: =D18-D22-D21-D20 -> 135038.28 | E23: =E18-E22-E21-E20 -> 177870.84 | F23: =F18-F22-F21-F20 -> 139228.43 | G23: =G18-G22-G21-G20 -> 150764.34 | H23: =H18-H22-H21-H20 -> 153932.9 | I23: =I18-I22-I21-I20 -> 201974.08 | J23: =J18-J22-J21-J20 -> 110764.1 | ... L23: =L18-L22-L21-L20 -> -3632.72 | M23: =SUM(C23:L23) -> 1508158
C28: Rótulos de Coluna
C29: 45658 | D29: 45689 | E29: 45717 | F29: 45748 | G29: 45778 | H29: 45809 | I29: 45839 | J29: 45870 | K29: 45901 | L29: 45931 | M29: Total Geral
B30: Soma de Daily | C30: 2989 | D30: 3586 | E30: 2975 | F30: 2889 | G30: 2991 | H30: 2836 | I30: 3475 | J30: 4264 | K30: 3703 | L30: 4249 | M30: 33957
B32: Total Daily | C32: (Tudo)
B34: Soma de Total | C34: Rótulos de Coluna
B35: Rótulos de Linha | C35: 45658 | D35: 45689 | E35: 45717 | F35: 45748 | G35: 45778 | H35: 45809 | I35: 45839 | J35: 45870 | K35: 45901 | L35: 45931 | M35: Total Geral
B36: Engineering | G36: 99071 | H36: 218005 | I36: 311616 | J36: 376866 | K36: 203550 | L36: 409240 | M36: 1618348
B37: Equipment Rental | C37: 122519.06 | D37: 135038.28 | E37: 177870.84 | F37: 139228.43 | G37: 150764.34 | H37: 153932.9 | I37: 201974.08 | J37: 110764.1 | K37: 319698.7 | L37: -3632.72 | M37: 1508158
B38: Inspection Contract - Fixed Team | C38: 2527553.8 | D38: 2567526.7 | E38: 2552345.8 | F38: 2697320.1 | G38: 2634521.7 | H38: 2782488.6 | I38: 2892340.2 | J38: 2697071.4 | K38: 2352708.2 | L38: 2671161 | M38: 26375037
B39: Inspection Contract - Variable | C39: 1334866.5 | D39: 2677055.4 | E39: 2151275.9 | F39: 1509970.1 | G39: 1423202.2 | H39: 1211994.1 | I39: 2040312.8 | J39: 3786060.2 | K39: 3665965.3 | L39: 5588411.2 | M39: 25389114
B40: Inspection Spot | C40: 448449.54 | D40: 669372.35 | E40: 1503300.3 | F40: 1471788.9 | G40: 1778504.7 | H40: 1893352 | I40: 1706242.1 | J40: 2291293.9 | K40: 1597185.1 | L40: 1779596.5 | M40: 15139085
B41: Maintenance Contract - Variable | C41: 1419140.7 | D41: 3502008.9 | E41: 1969628.1 | F41: 1074008.6 | G41: 904611.12 | H41: 869121.47 | I41: 1791653.9 | J41: 2118005.3 | K41: 1764911.9 | L41: 1560597.5 | M41: 16973687
B42: Maintenance Spot | C42: 2310328.4 | D42: 1489021.7 | E42: 1149356.1 | F42: 777935.93 | G42: 1370165.7 | H42: 878612.64 | I42: 1297140.8 | J42: 974947.05 | K42: 506769.78 | L42: 1243878.8 | M42: 11998157
B43: Total Geral | C43: 8162857.9 | D43: 11040023 | E43: 9503777 | F43: 7670252.1 | G43: 8360840.6 | H43: 8007506.7 | I43: 10241280 | J43: 12355008 | K43: 10410789 | L43: 13249252 | M43: 99001587
N44: Nov | O44: Dez
B45: Inspeção | C45: =SUM(C38:C40) -> 4310869.8 | D45: =SUM(D38:D40) -> 5913954.4 | E45: =SUM(E38:E40) -> 6206922 | F45: =SUM(F38:F40) -> 5679079.1 | G45: =SUM(G38:G40) -> 5836228.5 | H45: =SUM(H38:H40) -> 5887834.7 | I45: =SUM(I38:I40) -> 6638895.1 | J45: =SUM(J38:J40) -> 8774425.5 | ... L45: =SUM(L38:L40) -> 10039169 | N45: 9949954.5 | O45: 8989950 | P45: =SUM(C45:O45) -> 85843141
B46: Manutenção | C46: =SUM(C41:C42) -> 3729469.1 | D46: =SUM(D41:D42) -> 4991030.5 | E46: =SUM(E41:E42) -> 3118984.1 | F46: =SUM(F41:F42) -> 1851944.5 | G46: =SUM(G41:G42) -> 2274776.8 | H46: =SUM(H41:H42) -> 1747734.1 | I46: =SUM(I41:I42) -> 3088794.7 | J46: =SUM(J41:J42) -> 3092952.4 | ... L46: =SUM(L41:L42) -> 2804476.3 | N46: 987819 | O46: 1640483 | P46: =SUM(C46:O46) -> 31600146
B47: Engenharia | C47: =C36 -> 0 | D47: =D36 -> 0 | E47: =E36 -> 0 | F47: =F36 -> 0 | G47: =G36 -> 99071 | H47: =H36 -> 218005 | I47: =I36 -> 311616 | J47: =J36 -> 376866 | ... L47: =L36 -> 409240 | N47: 488345.72 | O47: 605301.44 | P47: =SUM(C47:O47) -> 2711995.2
B48: Outros | C48: =C43-C47-C46-C45 -> 122519.06 | D48: =D43-D47-D46-D45 -> 135038.28 | E48: =E43-E47-E46-E45 -> 177870.84 | F48: =F43-F47-F46-F45 -> 139228.43 | G48: =G43-G47-G46-G45 -> 150764.34 | H48: =H43-H47-H46-H45 -> 153932.9 | I48: =I43-I47-I46-I45 -> 201974.08 | J48: =J43-J47-J46-J45 -> 110764.1 | ... L48: =L43-L47-L46-L45 -> -3632.72 | N48: 0 | O48: 0 | P48: =SUM(C48:O48) -> 1508158
C49: =SUM(C45:C48) -> 8162857.9 | D49: =SUM(D45:D48) -> 11040023 | E49: =SUM(E45:E48) -> 9503777 | F49: =SUM(F45:F48) -> 7670252.1 | G49: =SUM(G45:G48) -> 8360840.6 | H49: =SUM(H45:H48) -> 8007506.7 | I49: =SUM(I45:I48) -> 10241280 | J49: =SUM(J45:J48) -> 12355008 | ... L49: =SUM(L45:L48) -> 13249252 | N49: =SUM(N45:N48) -> 11426119 | O49: =SUM(O45:O48) -> 11235734
B52: Total Daily | C52: (Tudo)
...

Sheet Comparação
B1: 46023 | C1: Daily | D1: R$ | E1: TM | F1: 46054 | G1: Daily | H1: R$ | I1: TM | J1: 46082 | K1: Daily | L1: R$ | M1: TM | N1: 46113 | O1: Daily | P1: R$ | Q1: TM | R1: 46143 | S1: Daily | T1: R$ | U1: TM | V1: 46174 | W1: Daily | X1: R$ | Y1: TM | Z1: 46204 | AA1: Daily | AB1: R$ | AC1: TM | AD1: 46235 | AE1: Daily | AF1: R$ | AG1: TM | AH1: 46266 | AI1: Daily | AJ1: R$ | AK1: TM | AL1: 46296 | AM1: Daily | AN1: R$ | AO1: TM | AP1: 46327 | AQ1: Daily | AR1: R$ | AS1: TM | AT1: 46357 | AU1: Daily | AV1: R$ | AW1: TM | AZ1: Q1.2026 | BA1: Q2.2026 | BB1: 45839 | BC1: %
B2: Inspection Contract - Fixed Team | C2: =SUMIFS(Input!$AA:$AA,Input!$A:$A,Comparação!B1,Input!$E:$E,Comparação!B2) -> 1448 | D2: =SUMIFS(Input!$K:$K,Input!$A:$A,Comparação!B1,Input!$E:$E,Comparação!B2) -> 2999216.4 | E2: =D2/C2 -> 2071.282 | F2: Inspection Contract - Fixed Team | G2: =SUMIFS(Input!$AA:$AA,Input!$A:$A,Comparação!F1,Input!$E:$E,Comparação!F2) -> 1301 | H2: =SUMIFS(Input!$K:$K,Input!$A:$A,Comparação!F1,Input!$E:$E,Comparação!F2) -> 2869507.2 | I2: =H2/G2 -> 2205.6166 | J2: Inspection Contract - Fixed Team | K2: =SUMIFS(Input!$AA:$AA,Input!$A:$A,Comparação!J1,Input!$E:$E,Comparação!J2) -> 1470 | L2: =SUMIFS(Input!$K:$K,Input!$A:$A,Comparação!J1,Input!$E:$E,Comparação!J2) -> 3000090.2 | M2: =L2/K2 -> 2040.8777 | N2: Inspection Contract - Fixed Team | O2: =SUMIFS(Input!$AA:$AA,Input!$A:$A,Comparação!N1,Input!$E:$E,Comparação!N2) -> 1427 | P2: =SUMIFS(Input!$K:$K,Input!$A:$A,Comparação!N1,Input!$E:$E,Comparação!N2) -> 2998666.3 | Q2: =P2/O2 -> 2101.378 | R2: Inspection Contract - Fixed Team | S2: =SUMIFS(Input!$AA:$AA,Input!$A:$A,Comparação!R1,Input!$E:$E,Comparação!R2) -> 1328 | T2: =SUMIFS(Input!$K:$K,Input!$A:$A,Comparação!R1,Input!$E:$E,Comparação!R2) -> 2751373.6 | U2: =T2/S2 -> 2071.8175 | V2: Inspection Contract - Fixed Team | W2: =SUMIFS(Input!$AA:$AA,Input!$A:$A,Comparação!V1,Input!$E:$E,Comparação!V2) -> 117 | X2: =SUMIFS(Input!$K:$K,Input!$A:$A,Comparação!V1,Input!$E:$E,Comparação!V2) -> 146563.82 | Y2: =X2/W2 -> 1252.6822 | Z2: Inspection Contract - Fixed Team | AA2: =SUMIFS(Input!$AA:$AA,Input!$A:$A,Comparação!Z1,Input!$E:$E,Comparação!Z2) -> 0 | AB2: =SUMIFS(Input!$K:$K,Input!$A:$A,Comparação!Z1,Input!$E:$E,Comparação!Z2) -> 0 | AC2: =AB2/AA2 -> #DIV/0! | AD2: Inspection Contract - Fixed Team | AE2: =SUMIFS(Input!$AA:$AA,Input!$A:$A,Comparação!AD1,Input!$E:$E,Comparação!AD2) -> 0 | AF2: =SUMIFS(Input!$K:$K,Input!$A:$A,Comparação!AD1,Input!$E:$E,Comparação!AD2) -> 0 | AG2: =AF2/AE2 -> #DIV/0! | AH2: Inspection Contract - Fixed Team | AI2: =SUMIFS(Input!$AA:$AA,Input!$A:$A,Comparação!AH1,Input!$E:$E,Comparação!AH2) -> 0 | AJ2: =SUMIFS(Input!$K:$K,Input!$A:$A,Comparação!AH1,Input!$E:$E,Comparação!AH2) -> 0 | AK2: =AJ2/AI2 -> #DIV/0! | AL2: Inspection Contract - Fixed Team | AM2: =SUMIFS(Input!$AA:$AA,Input!$A:$A,Comparação!AL1,Input!$E:$E,Comparação!AL2) -> 0 | AN2: =SUMIFS(Input!$K:$K,Input!$A:$A,Comparação!AL1,Input!$E:$E,Comparação!AL2) -> 0 | AO2: =AN2/AM2 -> #DIV/0! | AP2: Inspection Contract - Fixed Team | AQ2: =SUMIFS(Input!$AA:$AA,Input!$A:$A,Comparação!AP1,Input!$E:$E,Comparação!AP2) -> 0 | AR2: =SUMIFS(Input!$K:$K,Input!$A:$A,Comparação!AP1,Input!$E:$E,Comparação!AP2) -> 0 | AS2: =AR2/AQ2 -> #DIV/0! | AT2: Inspection Contract - Fixed Team | AU2: =SUMIFS(Input!$AA:$AA,Input!$A:$A,Comparação!AT1,Input!$E:$E,Comparação!AT2) -> 0 | AV2: =SUMIFS(Input!$K:$K,Input!$A:$A,Comparação!AT1,Input!$E:$E,Comparação!AT2) -> 0 | AW2: =AV2/AU2 -> #DIV/0! | AY2: Inspection Contract - Fixed Team | AZ2: =AVERAGE(E2,I2,M2) -> 2105.9254 | BA2: =AVERAGE(Q2,U2,Y2) -> 1808.6259 | BB2: =AC2 -> #DIV/0! | BC2: =BB2/AVERAGE(AZ2:BA2) -> #DIV/0!
B3: GranServices | C3: =SUMIFS(Input!$AA:$AA,Input!$A:$A,Comparação!$B$1,Input!$E:$E,Comparação!B2,Input!$F:$F,Comparação!B3) -> 0 | D3: =SUMIFS(Input!$K:$K,Input!$A:$A,Comparação!$B$1,Input!$E:$E,Comparação!$B$2,Input!$F:$F,Comparação!B3) -> 0 | F3: GranServices | G3: =SUMIFS(Input!$AA:$AA,Input!$A:$A,F1,Input!$E:$E,Comparação!F2,Input!$F:$F,Comparação!F3) -> 0 | H3: =SUMIFS(Input!$K:$K,Input!$A:$A,F1,Input!$E:$E,F2,Input!$F:$F,Comparação!F3) -> 0 | J3: GranServices | K3: =SUMIFS(Input!$AA:$AA,Input!$A:$A,$J$1,Input!$E:$E,Comparação!$J$2,Input!$F:$F,Comparação!J3) -> 0 | L3: =SUMIFS(Input!$K:$K,Input!$A:$A,$J$1,Input!$E:$E,$J$2,Input!$F:$F,Comparação!J3) -> 0 | M3: =IF(L3=0,"",L3/K3) | N3: GranServices | O3: =SUMIFS(Input!$AA:$AA,Input!$A:$A,$N$1,Input!$E:$E,Comparação!$N$2,Input!$F:$F,Comparação!N3) -> 0 | P3: =SUMIFS(Input!$K:$K,Input!$A:$A,$N$1,Input!$E:$E,$N$2,Input!$F:$F,Comparação!N3) -> 0 | Q3: =IF(P3=0,"",P3/O3) | R3: GranServices | S3: =SUMIFS(Input!$AA:$AA,Input!$A:$A,$R$1,Input!$E:$E,Comparação!$R$2,Input!$F:$F,Comparação!R3) -> 0 | T3: =SUMIFS(Input!$K:$K,Input!$A:$A,$R$1,Input!$E:$E,$R$2,Input!$F:$F,Comparação!R3) -> 0 | U3: =IF(T3=0,"",T3/S3) | V3: GranServices | W3: =SUMIFS(Input!$AA:$AA,Input!$A:$A,V1,Input!$E:$E,Comparação!V2,Input!$F:$F,Comparação!V3) -> 0 | X3: =SUMIFS(Input!$K:$K,Input!$A:$A,V1,Input!$E:$E,V2,Input!$F:$F,Comparação!V3) -> 0 | Y3: =IF(X3=0,"",X3/W3) | Z3: GranServices | AA3: =SUMIFS(Input!$AA:$AA,Input!$A:$A,Z1,Input!$E:$E,Comparação!Z2,Input!$F:$F,Comparação!Z3) -> 0 | AB3: =SUMIFS(Input!$K:$K,Input!$A:$A,Z1,Input!$E:$E,Z2,Input!$F:$F,Comparação!Z3) -> 0 | AC3: =IF(AB3=0,"",AB3/AA3) | AD3: GranServices | AE3: =SUMIFS(Input!$AA:$AA,Input!$A:$A,AD1,Input!$E:$E,Comparação!AD2,Input!$F:$F,Comparação!AD3) -> 0 | AF3: =SUMIFS(Input!$K:$K,Input!$A:$A,AD1,Input!$E:$E,AD2,Input!$F:$F,Comparação!AD3) -> 0 | AG3: =IF(AF3=0,"",AF3/AE3) | AH3: GranServices | AI3: =SUMIFS(Input!$AA:$AA,Input!$A:$A,AH1,Input!$E:$E,Comparação!AH2,Input!$F:$F,Comparação!AH3) -> 0 | AJ3: =SUMIFS(Input!$K:$K,Input!$A:$A,AH1,Input!$E:$E,AH2,Input!$F:$F,Comparação!AH3) -> 0 | AK3: =IF(AJ3=0,"",AJ3/AI3) | AL3: GranServices | AM3: =SUMIFS(Input!$AA:$AA,Input!$A:$A,AL1,Input!$E:$E,Comparação!AL2,Input!$F:$F,Comparação!AL3) -> 0 | AN3: =SUMIFS(Input!$K:$K,Input!$A:$A,AL1,Input!$E:$E,AL2,Input!$F:$F,Comparação!AL3) -> 0 | AO3: =IF(AN3=0,"",AN3/AM3) | AP3: GranServices | AQ3: =SUMIFS(Input!$AA:$AA,Input!$A:$A,AP1,Input!$E:$E,Comparação!AP2,Input!$F:$F,Comparação!AP3) -> 0 | AR3: =SUMIFS(Input!$K:$K,Input!$A:$A,AP1,Input!$E:$E,AP2,Input!$F:$F,Comparação!AP3) -> 0 | AS3: =IF(AR3=0,"",AR3/AQ3) | AT3: GranServices | AU3: =SUMIFS(Input!$AA:$AA,Input!$A:$A,AT1,Input!$E:$E,Comparação!AT2,Input!$F:$F,Comparação!AT3) -> 0 | AV3: =SUMIFS(Input!$K:$K,Input!$A:$A,AT1,Input!$E:$E,AT2,Input!$F:$F,Comparação!AT3) -> 0 | AW3: =IF(AV3=0,"",AV3/AU3) | AY3: GranServices
B4: Modec | C4: =SUMIFS(Input!$AA:$AA,Input!$A:$A,Comparação!$B$1,Input!$E:$E,Comparação!$B$2,Input!$F:$F,Comparação!B4) -> 0 | D4: =SUMIFS(Input!$K:$K,Input!$A:$A,Comparação!$B$1,Input!$E:$E,Comparação!$B$2,Input!$F:$F,Comparação!B4) -> 0 | F4: Modec | G4: =SUMIFS(Input!$AA:$AA,Input!$A:$A,$F$1,Input!$E:$E,Comparação!$F$2,Input!$F:$F,Comparação!F4) -> 0 | H4: =SUMIFS(Input!$K:$K,Input!$A:$A,$F$1,Input!$E:$E,$F$2,Input!$F:$F,Comparação!F4) -> 0 | J4: Modec | K4: =SUMIFS(Input!$AA:$AA,Input!$A:$A,$J$1,Input!$E:$E,Comparação!$J$2,Input!$F:$F,Comparação!J4) -> 0 | L4: =SUMIFS(Input!$K:$K,Input!$A:$A,$J$1,Input!$E:$E,$J$2,Input!$F:$F,Comparação!J4) -> 0 | M4: =IF(L4=0,"",L4/K4) | N4: Modec | O4: =SUMIFS(Input!$AA:$AA,Input!$A:$A,$N$1,Input!$E:$E,Comparação!$N$2,Input!$F:$F,Comparação!N4) -> 0 | P4: =SUMIFS(Input!$K:$K,Input!$A:$A,$N$1,Input!$E:$E,$N$2,Input!$F:$F,Comparação!N4) -> 0 | Q4: =IF(P4=0,"",P4/O4) | R4: Modec | S4: =SUMIFS(Input!$AA:$AA,Input!$A:$A,$R$1,Input!$E:$E,Comparação!$R$2,Input!$F:$F,Comparação!R4) -> 0 | T4: =SUMIFS(Input!$K:$K,Input!$A:$A,$R$1,Input!$E:$E,$R$2,Input!$F:$F,Comparação!R4) -> 0 | U4: =IF(T4=0,"",T4/S4) | V4: Modec | W4: =SUMIFS([1]Input!$AC:$AC,[1]Input!$A:$A,[1]Comparação!$V$1,[1]Input!$E:$E,[1]Comparação!$V$2,[1]Input!$F:$F,[1]Comparação!V4) -> #VALUE! | X4: =SUMIFS([1]Input!$M:$M,[1]Input!$A:$A,[1]Comparação!$V$1,[1]Input!$E:$E,[1]Comparação!$V$2,[1]Input!$F:$F,[1]Comparação!V4) -> #VALUE! | Y4: =IF(X4=0,"",X4/W4) -> #VALUE! | Z4: Modec | AA4: =SUMIFS([1]Input!$AC:$AC,[1]Input!$A:$A,[1]Comparação!$Z$1,[1]Input!$E:$E,[1]Comparação!$Z$2,[1]Input!$F:$F,[1]Comparação!Z4) -> #VALUE! | AB4: =SUMIFS([1]Input!$M:$M,[1]Input!$A:$A,[1]Comparação!$Z$1,[1]Input!$E:$E,[1]Comparação!$Z$2,[1]Input!$F:$F,[1]Comparação!Z4) -> #VALUE! | AC4: =IF(AB4=0,"",AB4/AA4) -> #VALUE! | AD4: Modec | AE4: =SUMIFS([1]Input!$AC:$AC,[1]Input!$A:$A,[1]Comparação!$AD$1,[1]Input!$E:$E,[1]Comparação!$AD$2,[1]Input!$F:$F,[1]Comparação!AD4) -> #VALUE! | AF4: =SUMIFS([1]Input!$M:$M,[1]Input!$A:$A,[1]Comparação!$AD$1,[1]Input!$E:$E,[1]Comparação!$AD$2,[1]Input!$F:$F,[1]Comparação!AD4) -> #VALUE! | AG4: =IF(AF4=0,"",AF4/AE4) -> #VALUE! | AH4: Modec | AI4: =SUMIFS([1]Input!$AC:$AC,[1]Input!$A:$A,[1]Comparação!$AH$1,[1]Input!$E:$E,[1]Comparação!$AH$2,[1]Input!$F:$F,[1]Comparação!AH4) -> #VALUE! | AJ4: =SUMIFS([1]Input!$M:$M,[1]Input!$A:$A,[1]Comparação!$AH$1,[1]Input!$E:$E,[1]Comparação!$AH$2,[1]Input!$F:$F,[1]Comparação!AH4) -> #VALUE! | AK4: =IF(AJ4=0,"",AJ4/AI4) -> #VALUE! | AL4: Modec | AM4: =SUMIFS([1]Input!$AC:$AC,[1]Input!$A:$A,[1]Comparação!$AL$1,[1]Input!$E:$E,[1]Comparação!$AL$2,[1]Input!$F:$F,[1]Comparação!AL4) -> #VALUE! | AN4: =SUMIFS([1]Input!$M:$M,[1]Input!$A:$A,[1]Comparação!$AL$1,[1]Input!$E:$E,[1]Comparação!$AL$2,[1]Input!$F:$F,[1]Comparação!AL4) -> #VALUE! | AO4: =IF(AN4=0,"",AN4/AM4) -> #VALUE! | AP4: Modec | AQ4: =SUMIFS([1]Input!$AC:$AC,[1]Input!$A:$A,[1]Comparação!$AP$1,[1]Input!$E:$E,[1]Comparação!$AP$2,[1]Input!$F:$F,[1]Comparação!AP4) -> #VALUE! | AR4: =SUMIFS([1]Input!$M:$M,[1]Input!$A:$A,[1]Comparação!$AP$1,[1]Input!$E:$E,[1]Comparação!$AP$2,[1]Input!$F:$F,[1]Comparação!AP4) -> #VALUE! | AS4: =IF(AR4=0,"",AR4/AQ4) -> #VALUE! | AT4: Modec | AU4: =SUMIFS([1]Input!$AC:$AC,[1]Input!$A:$A,[1]Comparação!$AT$1,[1]Input!$E:$E,[1]Comparação!$AT$2,[1]Input!$F:$F,[1]Comparação!AT4) -> #VALUE! | AV4: =SUMIFS([1]Input!$M:$M,[1]Input!$A:$A,[1]Comparação!$AT$1,[1]Input!$E:$E,[1]Comparação!$AT$2,[1]Input!$F:$F,[1]Comparação!AT4) -> #VALUE! | AW4: =IF(AV4=0,"",AV4/AU4) -> #VALUE! | AY4: Modec
B5: Transocean | C5: =SUMIFS(Input!$AA:$AA,Input!$A:$A,Comparação!$B$1,Input!$E:$E,Comparação!$B$2,Input!$F:$F,Comparação!B5) -> 533 | D5: =SUMIFS(Input!$K:$K,Input!$A:$A,Comparação!$B$1,Input!$E:$E,Comparação!$B$2,Input!$F:$F,Comparação!B5) -> 1187596.7 | E5: =D5/C5 -> 2228.1363 | F5: Transocean | G5: =SUMIFS(Input!$AA:$AA,Input!$A:$A,$F$1,Input!$E:$E,Comparação!$F$2,Input!$F:$F,Comparação!F5) -> 507 | H5: =SUMIFS(Input!$K:$K,Input!$A:$A,$F$1,Input!$E:$E,$F$2,Input!$F:$F,Comparação!F5) -> 1184635.2 | I5: =H5/G5 -> 2336.5586 | J5: Transocean | K5: =SUMIFS(Input!$AA:$AA,Input!$A:$A,$J$1,Input!$E:$E,Comparação!$J$2,Input!$F:$F,Comparação!J5) -> 557 | L5: =SUMIFS(Input!$K:$K,Input!$A:$A,$J$1,Input!$E:$E,$J$2,Input!$F:$F,Comparação!J5) -> 1178042.8 | M5: =IF(L5=0,"",L5/K5) -> 2114.9781 | N5: Transocean | O5: =SUMIFS(Input!$AA:$AA,Input!$A:$A,$N$1,Input!$E:$E,Comparação!$N$2,Input!$F:$F,Comparação!N5) -> 547 | P5: =SUMIFS(Input!$K:$K,Input!$A:$A,$N$1,Input!$E:$E,$N$2,Input!$F:$F,Comparação!N5) -> 1196923.8 | Q5: =IF(P5=0,"",P5/O5) -> 2188.1606 | R5: Transocean | S5: =SUMIFS(Input!$AA:$AA,Input!$A:$A,$R$1,Input!$E:$E,Comparação!$R$2,Input!$F:$F,Comparação!R5) -> 486 | T5: =SUMIFS(Input!$K:$K,Input!$A:$A,$R$1,Input!$E:$E,$R$2,Input!$F:$F,Comparação!R5) -> 1061018.8 | U5: =IF(T5=0,"",T5/S5) -> 2183.1663 | V5: Transocean | W5: =SUMIFS([1]Input!$AC:$AC,[1]Input!$A:$A,[1]Comparação!$V$1,[1]Input!$E:$E,[1]Comparação!$V$2,[1]Input!$F:$F,[1]Comparação!V5) -> #VALUE! | X5: =SUMIFS([1]Input!$M:$M,[1]Input!$A:$A,[1]Comparação!$V$1,[1]Input!$E:$E,[1]Comparação!$V$2,[1]Input!$F:$F,[1]Comparação!V5) -> #VALUE! | Y5: =IF(X5=0,"",X5/W5) -> #VALUE! | Z5: Transocean | AA5: =SUMIFS([1]Input!$AC:$AC,[1]Input!$A:$A,[1]Comparação!$Z$1,[1]Input!$E:$E,[1]Comparação!$Z$2,[1]Input!$F:$F,[1]Comparação!Z5) -> #VALUE! | AB5: =SUMIFS([1]Input!$M:$M,[1]Input!$A:$A,[1]Comparação!$Z$1,[1]Input!$E:$E,[1]Comparação!$Z$2,[1]Input!$F:$F,[1]Comparação!Z5) -> #VALUE! | AC5: =IF(AB5=0,"",AB5/AA5) -> #VALUE! | AD5: Transocean | AE5: =SUMIFS([1]Input!$AC:$AC,[1]Input!$A:$A,[1]Comparação!$AD$1,[1]Input!$E:$E,[1]Comparação!$AD$2,[1]Input!$F:$F,[1]Comparação!AD5) -> #VALUE! | AF5: =SUMIFS([1]Input!$M:$M,[1]Input!$A:$A,[1]Comparação!$AD$1,[1]Input!$E:$E,[1]Comparação!$AD$2,[1]Input!$F:$F,[1]Comparação!AD5) -> #VALUE! | AG5: =IF(AF5=0,"",AF5/AE5) -> #VALUE! | AH5: Transocean | AI5: =SUMIFS([1]Input!$AC:$AC,[1]Input!$A:$A,[1]Comparação!$AH$1,[1]Input!$E:$E,[1]Comparação!$AH$2,[1]Input!$F:$F,[1]Comparação!AH5) -> #VALUE! | AJ5: =SUMIFS([1]Input!$M:$M,[1]Input!$A:$A,[1]Comparação!$AH$1,[1]Input!$E:$E,[1]Comparação!$AH$2,[1]Input!$F:$F,[1]Comparação!AH5) -> #VALUE! | AK5: =IF(AJ5=0,"",AJ5/AI5) -> #VALUE! | AL5: Transocean | AM5: =SUMIFS([1]Input!$AC:$AC,[1]Input!$A:$A,[1]Comparação!$AL$1,[1]Input!$E:$E,[1]Comparação!$AL$2,[1]Input!$F:$F,[1]Comparação!AL5) -> #VALUE! | AN5: =SUMIFS([1]Input!$M:$M,[1]Input!$A:$A,[1]Comparação!$AL$1,[1]Input!$E:$E,[1]Comparação!$AL$2,[1]Input!$F:$F,[1]Comparação!AL5) -> #VALUE! | AO5: =IF(AN5=0,"",AN5/AM5) -> #VALUE! | AP5: Transocean | AQ5: =SUMIFS([1]Input!$AC:$AC,[1]Input!$A:$A,[1]Comparação!$AP$1,[1]Input!$E:$E,[1]Comparação!$AP$2,[1]Input!$F:$F,[1]Comparação!AP5) -> #VALUE! | AR5: =SUMIFS([1]Input!$M:$M,[1]Input!$A:$A,[1]Comparação!$AP$1,[1]Input!$E:$E,[1]Comparação!$AP$2,[1]Input!$F:$F,[1]Comparação!AP5) -> #VALUE! | AS5: =IF(AR5=0,"",AR5/AQ5) -> #VALUE! | AT5: Transocean | AU5: =SUMIFS([1]Input!$AC:$AC,[1]Input!$A:$A,[1]Comparação!$AT$1,[1]Input!$E:$E,[1]Comparação!$AT$2,[1]Input!$F:$F,[1]Comparação!AT5) -> #VALUE! | AV5: =SUMIFS([1]Input!$M:$M,[1]Input!$A:$A,[1]Comparação!$AT$1,[1]Input!$E:$E,[1]Comparação!$AT$2,[1]Input!$F:$F,[1]Comparação!AT5) -> #VALUE! | AW5: =IF(AV5=0,"",AV5/AU5) -> #VALUE! | AY5: Transocean
